<?xml version="1.0"?>
<robot xmlns:xacro="http://www.ros.org/wiki/xacro" name="mallard">

    <xacro:macro name="thruster_link" params="name xyz rpy">
      
      <joint name="${name}" type="revolute">
          <parent link="base_link"/>
          <child link="${name}"/>
          <origin xyz="${xyz}" rpy="${rpy}"/>
          <dynamics damping="1.0"/>
          <axis xyz="0 1 0"/>
          <limit effort="30" velocity="5.0" lower="-${PI}" upper="${PI}" />
      </joint>
      
      <link name="${name}">      
          <visual name="${name}_1">
              <geometry>
                  <cylinder length="${tl1}" radius="${tr1}"/>
              </geometry>
              <material name="blue">
                  <color rgba="0 0 0.8 1"/>
              </material>
          </visual>  
          <visual name="${name}_2">
              <origin xyz="0 0 ${tl2/4}"/>
              <geometry>
                  <cylinder length="${tl2}" radius="${tr2}"/>
              </geometry>
              <material name="blue">
                 <color rgba="0 0 0.8 1"/>
              </material>
          </visual>  
          <inertial>
              <mass  value="0.3"/>
              <inertia ixx="0.001"
                       ixy="0.0"
                       ixz="0.0"
                       iyy="0.001"
                       iyz="0.0"
                       izz="0.001"/>
          </inertial>  
      </link> 

      <gazebo reference="${name}">
          <material>Gazebo/Blue</material>
      </gazebo>

      <buoyancy>
          <compensation>0.6</compensation>
      </buoyancy>
  </xacro:macro> 

</robot>